<sdf version='1.4'>
  <world name='default'>
    <light name='sun' type='directional'>
      <cast_shadows>1</cast_shadows>
      <pose>0 0 10 0 -0 0</pose>
      <diffuse>0.8 0.8 0.8 1</diffuse>
      <specular>0.2 0.2 0.2 1</specular>
      <attenuation>
        <range>1000</range>
        <constant>0.9</constant>
        <linear>0.01</linear>
        <quadratic>0.001</quadratic>
      </attenuation>
      <direction>-0.5 0.1 -0.9</direction>
    </light>
    <model name='ground_plane'>
      <static>1</static>
      <link name='link'>
        <collision name='collision'>
          <geometry>
            <plane>
              <normal>0 0 1</normal>
              <size>100 100</size>
            </plane>
          </geometry>
          <surface>
            <friction>
              <ode>
                <mu>100</mu>
                <mu2>50</mu2>
              </ode>
            </friction>
            <bounce/>
            <contact>
              <ode/>
            </contact>
          </surface>
          <max_contacts>10</max_contacts>
        </collision>
        <visual name='visual'>
          <cast_shadows>0</cast_shadows>
          <geometry>
            <plane>
              <normal>0 0 1</normal>
              <size>100 100</size>
            </plane>
          </geometry>
          <material>
            <script>
              <uri>file://media/materials/scripts/gazebo.material</uri>
              <name>Gazebo/Grey</name>
            </script>
          </material>
        </visual>
        <velocity_decay>
          <linear>0</linear>
          <angular>0</angular>
        </velocity_decay>
        <self_collide>0</self_collide>
        <kinematic>0</kinematic>
        <gravity>1</gravity>
      </link>
    </model>
    <physics type='ode'>
      <max_step_size>0.001</max_step_size>
      <real_time_factor>1</real_time_factor>
      <real_time_update_rate>1000</real_time_update_rate>
      <gravity>0 0 -9.8</gravity>
    </physics>
    <scene>
      <ambient>0.4 0.4 0.4 1</ambient>
      <background>0.7 0.7 0.7 1</background>
      <shadows>1</shadows>
    </scene>
    <model name='youbot'>
      <link name='base_footprint'>
        <pose>0 0 0 0 -0 0</pose>
        <inertial>
          <pose>-0.000884992 0 0.00310102 0 -0 0</pose>
          <mass>24.381</mass>
          <inertia>
            <ixx>6.87669</ixx>
            <ixy>-0.00971993</ixy>
            <ixz>1.29491</ixz>
            <iyy>6.96764</iyy>
            <iyz>-0.00737958</iyz>
            <izz>4.97691</izz>
          </inertia>
        </inertial>
        <collision name='base_footprint_collision'>
          <pose>0 0 -0.05 0 -0 0</pose>
          <geometry>
            <box>
              <size>0.001 0.001 0.001</size>
            </box>
          </geometry>
          <max_contacts>10</max_contacts>
          <surface>
            <bounce/>
            <friction>
              <ode/>
            </friction>
            <contact>
              <ode/>
            </contact>
          </surface>
        </collision>
        <collision name='base_footprint_collision_arm_link_0'>
          <pose>0.143 0 0.046 0 -0 0</pose>
          <geometry>
            <mesh>
              <scale>1 1 1</scale>
              <uri>/home/shehzad/ros_ws/hydro/robocupwork_ws/src/youbot_description/meshes/youbot_arm/arm0_convex.dae</uri>
            </mesh>
          </geometry>
          <surface>
            <contact>
              <ode/>
            </contact>
            <friction>
              <ode/>
            </friction>
            <bounce/>
          </surface>
          <max_contacts>10</max_contacts>
        </collision>
        <collision name='base_footprint_collision_base_laser_front_link'>
          <pose>0.3 0 -0.03 0 -0 0</pose>
          <geometry>
            <mesh>
              <scale>1 1 1</scale>
              <uri>/home/shehzad/ros_ws/hydro/robocupwork_ws/src/youbot_description/meshes/sensors/hokuyo_convex.dae</uri>
            </mesh>
          </geometry>
          <surface>
            <contact>
              <ode/>
            </contact>
            <friction>
              <ode/>
            </friction>
            <bounce/>
          </surface>
          <max_contacts>10</max_contacts>
        </collision>
        <collision name='base_footprint_collision_base_laser_rear_link'>
          <pose>-0.3 0 -0.03 0 -0 -3.14159</pose>
          <geometry>
            <mesh>
              <scale>1 1 1</scale>
              <uri>/home/shehzad/ros_ws/hydro/robocupwork_ws/src/youbot_description/meshes/sensors/hokuyo_convex.dae</uri>
            </mesh>
          </geometry>
          <surface>
            <contact>
              <ode/>
            </contact>
            <friction>
              <ode/>
            </friction>
            <bounce/>
          </surface>
          <max_contacts>10</max_contacts>
        </collision>
        <collision name='base_footprint_collision_base_link'>
          <pose>0 0 0 0 -0 0</pose>
          <geometry>
            <mesh>
              <scale>1 1 1</scale>
              <uri>/home/shehzad/ros_ws/hydro/robocupwork_ws/src/youbot_description/meshes/youbot_base/base_convex.dae</uri>
            </mesh>
          </geometry>
          <max_contacts>10</max_contacts>
          <surface>
            <bounce/>
            <friction>
              <ode/>
            </friction>
            <contact>
              <ode/>
            </contact>
          </surface>
        </collision>
        <collision name='base_footprint_collision_plate_link'>
          <pose>-0.159 0 0.046 0 -0 0</pose>
          <geometry>
            <mesh>
              <scale>1 1 1</scale>
              <uri>/home/shehzad/ros_ws/hydro/robocupwork_ws/src/youbot_description/meshes/youbot_plate/plate_convex.dae</uri>
            </mesh>
          </geometry>
          <max_contacts>10</max_contacts>
          <surface>
            <bounce/>
            <friction>
              <ode/>
            </friction>
            <contact>
              <ode/>
            </contact>
          </surface>
        </collision>
        <visual name='base_footprint_visual'>
          <pose>0 0 0 0 -0 0</pose>
          <geometry>
            <box>
              <size>0.001 0.001 0.001</size>
            </box>
          </geometry>
        </visual>
        <visual name='base_footprint_visual_arm_link_0'>
          <pose>0.143 0 0.046 0 -0 0</pose>
          <geometry>
            <mesh>
              <scale>1 1 1</scale>
              <uri>/home/shehzad/ros_ws/hydro/robocupwork_ws/src/youbot_description/meshes/youbot_arm/arm0.dae</uri>
            </mesh>
          </geometry>
          <material>
            <script>
              <name>youbot/DarkGrey</name>
              <uri>__default__</uri>
            </script>
          </material>
        </visual>
        <visual name='base_footprint_visual_base_laser_front_link'>
          <pose>0.3 0 -0.03 0 -0 0</pose>
          <geometry>
            <mesh>
              <scale>1 1 1</scale>
              <uri>/home/shehzad/ros_ws/hydro/robocupwork_ws/src/youbot_description/meshes/sensors/hokuyo.dae</uri>
            </mesh>
          </geometry>
        </visual>
        <visual name='base_footprint_visual_base_laser_rear_link'>
          <pose>-0.3 0 -0.03 0 -0 -3.14159</pose>
          <geometry>
            <mesh>
              <scale>1 1 1</scale>
              <uri>/home/shehzad/ros_ws/hydro/robocupwork_ws/src/youbot_description/meshes/sensors/hokuyo.dae</uri>
            </mesh>
          </geometry>
        </visual>
        <visual name='base_footprint_visual_base_link'>
          <pose>0 0 0 0 -0 0</pose>
          <geometry>
            <mesh>
              <scale>1 1 1</scale>
              <uri>/home/shehzad/ros_ws/hydro/robocupwork_ws/src/youbot_description/meshes/youbot_base/base.dae</uri>
            </mesh>
          </geometry>
        </visual>
        <visual name='base_footprint_visual_plate_link'>
          <pose>-0.159 0 0.046 0 -0 0</pose>
          <geometry>
            <mesh>
              <scale>1 1 1</scale>
              <uri>/home/shehzad/ros_ws/hydro/robocupwork_ws/src/youbot_description/meshes/youbot_plate/plate.dae</uri>
            </mesh>
          </geometry>
        </visual>
        <velocity_decay>
          <linear>0</linear>
          <angular>0</angular>
        </velocity_decay>
        <velocity_decay>
          <linear>0</linear>
          <angular>0</angular>
        </velocity_decay>
        <sensor name='base_laser_front' type='ray'>
          <always_on>1</always_on>
          <update_rate>10</update_rate>
          <visualize>0</visualize>
          <ray>
            <scan>
              <horizontal>
                <samples>150</samples>
                <resolution>1</resolution>
                <min_angle>-1.57</min_angle>
                <max_angle>1.57</max_angle>
              </horizontal>
            </scan>
            <range>
              <min>0.05</min>
              <max>5.6</max>
              <resolution>0.36</resolution>
            </range>
          </ray>
          <plugin name='gazebo_ros_base_laser_front_controller' filename='libgazebo_ros_laser.so'>
            <gaussianNoise>0.005</gaussianNoise>
            <alwaysOn>true</alwaysOn>
            <updateRate>10</updateRate>
            <topicName>scan_front</topicName>
            <frameName>/base_laser_front_link</frameName>
            <robotNamespace>/</robotNamespace>
          </plugin>
          <pose>0.3 0 -0.03 0 -0 0</pose>
        </sensor>
        <gravity>1</gravity>
        <velocity_decay>
          <linear>0</linear>
          <angular>0</angular>
        </velocity_decay>
        <self_collide>0</self_collide>
        <sensor name='base_laser_rear' type='ray'>
          <always_on>1</always_on>
          <update_rate>10</update_rate>
          <visualize>0</visualize>
          <ray>
            <scan>
              <horizontal>
                <samples>150</samples>
                <resolution>1</resolution>
                <min_angle>-1.57</min_angle>
                <max_angle>1.57</max_angle>
              </horizontal>
            </scan>
            <range>
              <min>0.05</min>
              <max>5.6</max>
              <resolution>0.36</resolution>
            </range>
          </ray>
          <plugin name='gazebo_ros_base_laser_rear_controller' filename='libgazebo_ros_laser.so'>
            <gaussianNoise>0.005</gaussianNoise>
            <alwaysOn>true</alwaysOn>
            <updateRate>10</updateRate>
            <topicName>scan_rear</topicName>
            <frameName>/base_laser_rear_link</frameName>
            <robotNamespace>/</robotNamespace>
          </plugin>
          <pose>-0.3 0 -0.03 0 -0 -3.14159</pose>
        </sensor>
        <kinematic>0</kinematic>
      </link>
      <link name='arm_link_1'>
        <pose>0.167 0 0.142 0 -0 2.96706</pose>
        <inertial>
          <pose>0.01489 0.00213 0.00213 0 -0 0</pose>
          <mass>1.39</mass>
          <inertia>
            <ixx>0.0029525</ixx>
            <ixy>0</ixy>
            <ixz>0</ixz>
            <iyy>0.0060091</iyy>
            <iyz>0</iyz>
            <izz>0.0058821</izz>
          </inertia>
        </inertial>
        <collision name='arm_link_1_collision'>
          <pose>0 0 0 0 -0 0</pose>
          <geometry>
            <mesh>
              <scale>1 1 1</scale>
              <uri>/home/shehzad/ros_ws/hydro/robocupwork_ws/src/youbot_description/meshes/youbot_arm/arm1_convex.dae</uri>
            </mesh>
          </geometry>
          <surface>
            <contact>
              <ode/>
            </contact>
            <friction>
              <ode/>
            </friction>
            <bounce/>
          </surface>
          <max_contacts>10</max_contacts>
        </collision>
        <visual name='arm_link_1_visual'>
          <pose>0 0 0 0 -0 0</pose>
          <geometry>
            <mesh>
              <scale>1 1 1</scale>
              <uri>/home/shehzad/ros_ws/hydro/robocupwork_ws/src/youbot_description/meshes/youbot_arm/arm1.dae</uri>
            </mesh>
          </geometry>
        </visual>
        <gravity>1</gravity>
        <velocity_decay>
          <linear>0</linear>
          <angular>0</angular>
        </velocity_decay>
        <self_collide>0</self_collide>
        <kinematic>0</kinematic>
      </link>
      <joint name='arm_joint_1' type='revolute'>
        <child>arm_link_1</child>
        <parent>base_footprint</parent>
        <axis>
          <xyz>0 0 -1</xyz>
          <limit>
            <lower>0</lower>
            <upper>5.89921</upper>
            <effort>9.5</effort>
            <velocity>1.5708</velocity>
          </limit>
          <dynamics>
            <damping>1</damping>
          </dynamics>
        </axis>
      </joint>
      <link name='arm_link_2'>
        <pose>0.134501 0.00573039 0.161 1.31349e-16 -1.13446 2.96706</pose>
        <inertial>
          <pose>0.01053 -0.0307 0.08597 0 -0 0</pose>
          <mass>1.318</mass>
          <inertia>
            <ixx>0.0031145</ixx>
            <ixy>0</ixy>
            <ixz>0</ixz>
            <iyy>0.0005843</iyy>
            <iyz>0</iyz>
            <izz>0.0031631</izz>
          </inertia>
        </inertial>
        <collision name='arm_link_2_collision'>
          <pose>0 -0.032 0.078 0 -0 0</pose>
          <geometry>
            <mesh>
              <scale>1 1 1</scale>
              <uri>/home/shehzad/ros_ws/hydro/robocupwork_ws/src/youbot_description/meshes/youbot_arm/arm2_convex.dae</uri>
            </mesh>
          </geometry>
          <surface>
            <contact>
              <ode/>
            </contact>
            <friction>
              <ode/>
            </friction>
            <bounce/>
          </surface>
          <max_contacts>10</max_contacts>
        </collision>
        <visual name='arm_link_2_visual'>
          <pose>0 -0.032 0.078 0 -0 0</pose>
          <geometry>
            <mesh>
              <scale>1 1 1</scale>
              <uri>/home/shehzad/ros_ws/hydro/robocupwork_ws/src/youbot_description/meshes/youbot_arm/arm2.dae</uri>
            </mesh>
          </geometry>
        </visual>
        <gravity>1</gravity>
        <velocity_decay>
          <linear>0</linear>
          <angular>0</angular>
        </velocity_decay>
        <self_collide>0</self_collide>
        <kinematic>0</kinematic>
      </link>
      <joint name='arm_joint_2' type='revolute'>
        <child>arm_link_2</child>
        <parent>arm_link_1</parent>
        <axis>
          <xyz>-0.173648 -0.984808 0</xyz>
          <limit>
            <lower>0</lower>
            <upper>2.70526</upper>
            <effort>9.5</effort>
            <velocity>1.5708</velocity>
          </limit>
          <dynamics>
            <damping>1</damping>
          </dynamics>
        </axis>
      </joint>
      <link name='arm_link_3'>
        <pose>0.272845 -0.0186633 0.226506 -2.66145e-16 1.41372 2.96706</pose>
        <inertial>
          <pose>0.0001 0.0207 0.07107 0 -0 0</pose>
          <mass>0.821</mass>
          <inertia>
            <ixx>0.00172767</ixx>
            <ixy>0</ixy>
            <ixz>0</ixz>
            <iyy>0.00041967</iyy>
            <iyz>0</iyz>
            <izz>0.0018468</izz>
          </inertia>
        </inertial>
        <collision name='arm_link_3_collision'>
          <pose>0 0.028 0.079 0 -0 0</pose>
          <geometry>
            <mesh>
              <scale>1 1 1</scale>
              <uri>/home/shehzad/ros_ws/hydro/robocupwork_ws/src/youbot_description/meshes/youbot_arm/arm3_convex.dae</uri>
            </mesh>
          </geometry>
          <surface>
            <contact>
              <ode/>
            </contact>
            <friction>
              <ode/>
            </friction>
            <bounce/>
          </surface>
          <max_contacts>10</max_contacts>
        </collision>
        <visual name='arm_link_3_visual'>
          <pose>0 0.028 0.079 0 -0 0</pose>
          <geometry>
            <mesh>
              <scale>1 1 1</scale>
              <uri>/home/shehzad/ros_ws/hydro/robocupwork_ws/src/youbot_description/meshes/youbot_arm/arm3.dae</uri>
            </mesh>
          </geometry>
        </visual>
        <gravity>1</gravity>
        <velocity_decay>
          <linear>0</linear>
          <angular>0</angular>
        </velocity_decay>
        <self_collide>0</self_collide>
        <kinematic>0</kinematic>
      </link>
      <joint name='arm_joint_3' type='revolute'>
        <child>arm_link_3</child>
        <parent>arm_link_2</parent>
        <axis>
          <xyz>-0.173648 -0.984808 0</xyz>
          <limit>
            <lower>-5.18363</lower>
            <upper>0</upper>
            <effort>6</effort>
            <velocity>1.5708</velocity>
          </limit>
          <dynamics>
            <damping>1</damping>
          </dynamics>
        </axis>
      </joint>
      <link name='arm_link_4'>
        <pose>0.141533 0.00449058 0.247624 0 -0.375246 2.96706</pose>
        <inertial>
          <pose>0.00011 -0.02 0.05019 0 -0 0</pose>
          <mass>0.769</mass>
          <inertia>
            <ixx>0.0006764</ixx>
            <ixy>0</ixy>
            <ixz>0</ixz>
            <iyy>0.0010573</iyy>
            <iyz>0</iyz>
            <izz>0.000661</izz>
          </inertia>
        </inertial>
        <collision name='arm_link_4_collision'>
          <pose>0 -0.01 0.029 0 -0 0</pose>
          <geometry>
            <mesh>
              <scale>1 1 1</scale>
              <uri>/home/shehzad/ros_ws/hydro/robocupwork_ws/src/youbot_description/meshes/youbot_arm/arm4_convex.dae</uri>
            </mesh>
          </geometry>
          <surface>
            <contact>
              <ode/>
            </contact>
            <friction>
              <ode/>
            </friction>
            <bounce/>
          </surface>
          <max_contacts>10</max_contacts>
        </collision>
        <visual name='arm_link_4_visual'>
          <pose>0 -0.01 0.029 0 -0 0</pose>
          <geometry>
            <mesh>
              <scale>1 1 1</scale>
              <uri>/home/shehzad/ros_ws/hydro/robocupwork_ws/src/youbot_description/meshes/youbot_arm/arm4.dae</uri>
            </mesh>
          </geometry>
        </visual>
        <gravity>1</gravity>
        <velocity_decay>
          <linear>0</linear>
          <angular>0</angular>
        </velocity_decay>
        <self_collide>0</self_collide>
        <kinematic>0</kinematic>
      </link>
      <joint name='arm_joint_4' type='revolute'>
        <child>arm_link_4</child>
        <parent>arm_link_3</parent>
        <axis>
          <xyz>-0.173648 -0.984808 0</xyz>
          <limit>
            <lower>0</lower>
            <upper>3.57792</upper>
            <effort>2</effort>
            <velocity>1.5708</velocity>
          </limit>
          <dynamics>
            <damping>1</damping>
          </dynamics>
        </axis>
      </joint>
      <link name='arm_link_5'>
        <pose>0.190287 -0.00410605 0.367846 -0.0850522 0.365926 -0.408446</pose>
        <inertial>
          <pose>0 0.00100388 -0.0146915 0 -0 0</pose>
          <mass>0.787</mass>
          <inertia>
            <ixx>0.0102182</ixx>
            <ixy>0</ixy>
            <ixz>0</ixz>
            <iyy>0.0101849</iyy>
            <iyz>1.68952e-06</iyz>
            <izz>0.010069</izz>
          </inertia>
        </inertial>
        <collision name='arm_link_5_collision'>
          <pose>0.003 0 -0.034 0 -0 0</pose>
          <geometry>
            <mesh>
              <scale>1 1 1</scale>
              <uri>/home/shehzad/ros_ws/hydro/robocupwork_ws/src/youbot_description/meshes/youbot_arm/arm5_convex.dae</uri>
            </mesh>
          </geometry>
          <surface>
            <contact>
              <ode/>
            </contact>
            <friction>
              <ode/>
            </friction>
            <bounce/>
          </surface>
          <max_contacts>10</max_contacts>
        </collision>
        <collision name='arm_link_5_collision_gripper_palm_link'>
          <pose>0 0 0 0 -0 0</pose>
          <geometry>
            <mesh>
              <scale>1 1 1</scale>
              <uri>/home/shehzad/ros_ws/hydro/robocupwork_ws/src/youbot_description/meshes/youbot_gripper/palm_convex.dae</uri>
            </mesh>
          </geometry>
          <surface>
            <contact>
              <ode/>
            </contact>
            <friction>
              <ode/>
            </friction>
            <bounce/>
          </surface>
          <surface>
            <contact>
              <ode/>
            </contact>
            <friction>
              <ode/>
            </friction>
          </surface>
          <max_contacts>10</max_contacts>
        </collision>
        <visual name='arm_link_5_visual'>
          <pose>0.003 0 -0.034 0 -0 0</pose>
          <geometry>
            <mesh>
              <scale>1 1 1</scale>
              <uri>/home/shehzad/ros_ws/hydro/robocupwork_ws/src/youbot_description/meshes/youbot_arm/arm5.dae</uri>
            </mesh>
          </geometry>
        </visual>
        <visual name='arm_link_5_visual_gripper_palm_link'>
          <pose>0 0 0 0 -0 0</pose>
          <geometry>
            <mesh>
              <scale>1 1 1</scale>
              <uri>/home/shehzad/ros_ws/hydro/robocupwork_ws/src/youbot_description/meshes/youbot_gripper/palm.dae</uri>
            </mesh>
          </geometry>
          <material>
            <script>
              <name>Gazebo/Black</name>
              <uri>__default__</uri>
            </script>
          </material>
        </visual>
        <velocity_decay>
          <linear>0</linear>
          <angular>0</angular>
        </velocity_decay>
        <gravity>1</gravity>
        <velocity_decay>
          <linear>0</linear>
          <angular>0</angular>
        </velocity_decay>
        <self_collide>1</self_collide>
        <kinematic>0</kinematic>
      </link>
      <joint name='arm_joint_5' type='revolute'>
        <child>arm_link_5</child>
        <parent>arm_link_4</parent>
        <axis>
          <xyz>-0.360933 0.063642 -0.930418</xyz>
          <limit>
            <lower>0</lower>
            <upper>5.84685</upper>
            <effort>1</effort>
            <velocity>1.5708</velocity>
          </limit>
          <dynamics>
            <damping>1</damping>
          </dynamics>
        </axis>
      </joint>
      <link name='gripper_finger_link_l'>
        <pose>0.21326 -0.00110518 0.408579 0.0850522 -0.365926 2.73315</pose>
        <inertial>
          <pose>0 -0.001 0 0 -0 0</pose>
          <mass>0.01</mass>
          <inertia>
            <ixx>0.01</ixx>
            <ixy>0</ixy>
            <ixz>0</ixz>
            <iyy>0.01</iyy>
            <iyz>0</iyz>
            <izz>0.01</izz>
          </inertia>
        </inertial>
        <collision name='gripper_finger_link_l_collision'>
          <pose>0 0 0 0 -0 0</pose>
          <geometry>
            <mesh>
              <scale>1 1 1</scale>
              <uri>/home/shehzad/ros_ws/hydro/robocupwork_ws/src/youbot_description/meshes/youbot_gripper/finger_convex.dae</uri>
            </mesh>
          </geometry>
          <max_contacts>10</max_contacts>
          <surface>
            <bounce/>
            <friction>
              <ode/>
            </friction>
            <contact>
              <ode/>
            </contact>
          </surface>
        </collision>
        <visual name='gripper_finger_link_l_visual'>
          <pose>0 0 0 0 -0 0</pose>
          <geometry>
            <mesh>
              <scale>1 1 1</scale>
              <uri>/home/shehzad/ros_ws/hydro/robocupwork_ws/src/youbot_description/meshes/youbot_gripper/finger.dae</uri>
            </mesh>
          </geometry>
        </visual>
        <velocity_decay>
          <linear>0</linear>
          <angular>0</angular>
        </velocity_decay>
        <self_collide>0</self_collide>
        <kinematic>0</kinematic>
        <gravity>1</gravity>
      </link>
      <joint name='gripper_finger_joint_l' type='prismatic'>
        <child>gripper_finger_link_l</child>
        <parent>arm_link_5</parent>
        <axis>
          <xyz>0.367852 0.926495 -0.0793254</xyz>
          <limit>
            <lower>0</lower>
            <upper>0.0115</upper>
            <effort>1</effort>
            <velocity>0.1</velocity>
          </limit>
          <dynamics>
            <damping>1</damping>
          </dynamics>
        </axis>
      </joint>
      <link name='gripper_finger_link_r'>
        <pose>0.207375 -0.0159291 0.409848 -0.0850522 0.365926 -0.408446</pose>
        <inertial>
          <pose>0 -0.001 0 0 -0 0</pose>
          <mass>0.01</mass>
          <inertia>
            <ixx>0.01</ixx>
            <ixy>0</ixy>
            <ixz>0</ixz>
            <iyy>0.01</iyy>
            <iyz>0</iyz>
            <izz>0.01</izz>
          </inertia>
        </inertial>
        <collision name='gripper_finger_link_r_collision'>
          <pose>0 0 0 0 -0 0</pose>
          <geometry>
            <mesh>
              <scale>1 1 1</scale>
              <uri>/home/shehzad/ros_ws/hydro/robocupwork_ws/src/youbot_description/meshes/youbot_gripper/finger_convex.dae</uri>
            </mesh>
          </geometry>
          <max_contacts>10</max_contacts>
          <surface>
            <bounce/>
            <friction>
              <ode/>
            </friction>
            <contact>
              <ode/>
            </contact>
          </surface>
        </collision>
        <visual name='gripper_finger_link_r_visual'>
          <pose>0 0 0 0 -0 0</pose>
          <geometry>
            <mesh>
              <scale>1 1 1</scale>
              <uri>/home/shehzad/ros_ws/hydro/robocupwork_ws/src/youbot_description/meshes/youbot_gripper/finger.dae</uri>
            </mesh>
          </geometry>
        </visual>
        <velocity_decay>
          <linear>0</linear>
          <angular>0</angular>
        </velocity_decay>
        <self_collide>0</self_collide>
        <kinematic>0</kinematic>
        <gravity>1</gravity>
      </link>
      <joint name='gripper_finger_joint_r' type='prismatic'>
        <child>gripper_finger_link_r</child>
        <parent>arm_link_5</parent>
        <axis>
          <xyz>-0.367852 -0.926495 0.0793254</xyz>
          <limit>
            <lower>0</lower>
            <upper>0.0115</upper>
            <effort>1</effort>
            <velocity>0.1</velocity>
          </limit>
          <dynamics>
            <damping>1</damping>
          </dynamics>
        </axis>
      </joint>
      <link name='caster_link_bl'>
        <pose>-0.228 0.158 -0.034 0 -0 0</pose>
        <inertial>
          <pose>0 0 0 0 -0 0</pose>
          <mass>0.1</mass>
          <inertia>
            <ixx>0.0124118</ixx>
            <ixy>-0.000711734</ixy>
            <ixz>0.00050273</ixz>
            <iyy>0.0152182</iyy>
            <iyz>-4.27347e-06</iyz>
            <izz>0.011764</izz>
          </inertia>
        </inertial>
        <gravity>1</gravity>
        <velocity_decay>
          <linear>0</linear>
          <angular>0</angular>
        </velocity_decay>
        <self_collide>0</self_collide>
        <kinematic>0</kinematic>
      </link>
      <joint name='caster_joint_bl' type='revolute'>
        <child>caster_link_bl</child>
        <parent>base_footprint</parent>
        <axis>
          <xyz>0 0 1</xyz>
          <limit>
            <lower>-1e+16</lower>
            <upper>1e+16</upper>
          </limit>
          <dynamics>
            <damping>1</damping>
          </dynamics>
        </axis>
      </joint>
      <link name='wheel_link_bl'>
        <pose>-0.228 0.158 -0.034 0 -0 0</pose>
        <inertial>
          <pose>0 0 0 0 -0 0</pose>
          <mass>0.4</mass>
          <inertia>
            <ixx>0.0124118</ixx>
            <ixy>-0.000711734</ixy>
            <ixz>0.00050273</ixz>
            <iyy>0.0152182</iyy>
            <iyz>-4.27347e-06</iyz>
            <izz>0.011764</izz>
          </inertia>
        </inertial>
        <collision name='wheel_link_bl_collision'>
          <pose>0 0 0 1.5708 -0 0</pose>
          <geometry>
            <cylinder>
              <length>0.05</length>
              <radius>0.05</radius>
            </cylinder>
          </geometry>
          <surface>
            <contact>
              <ode>
                <kp>1e+06</kp>
                <kd>100</kd>
              </ode>
            </contact>
            <friction>
              <ode/>
            </friction>
            <bounce/>
          </surface>
          <max_contacts>10</max_contacts>
        </collision>
        <visual name='wheel_link_bl_visual'>
          <pose>0 0 0 0 -0 0</pose>
          <geometry>
            <sphere>
              <radius>0.05</radius>
            </sphere>
          </geometry>
          <material>
            <script>
              <name>youbot/Orange</name>
              <uri>__default__</uri>
            </script>
          </material>
        </visual>
        <gravity>1</gravity>
        <velocity_decay>
          <linear>0</linear>
          <angular>0</angular>
        </velocity_decay>
        <self_collide>0</self_collide>
        <kinematic>0</kinematic>
      </link>
      <joint name='wheel_joint_bl' type='revolute'>
        <child>wheel_link_bl</child>
        <parent>caster_link_bl</parent>
        <axis>
          <xyz>0 1 0</xyz>
          <limit>
            <lower>-1e+16</lower>
            <upper>1e+16</upper>
          </limit>
          <dynamics>
            <damping>1</damping>
          </dynamics>
        </axis>
      </joint>
      <link name='caster_link_br'>
        <pose>-0.228 -0.158 -0.034 0 -0 0</pose>
        <inertial>
          <pose>0 0 0 0 -0 0</pose>
          <mass>0.1</mass>
          <inertia>
            <ixx>0.0124118</ixx>
            <ixy>-0.000711734</ixy>
            <ixz>0.00050273</ixz>
            <iyy>0.0152182</iyy>
            <iyz>-4.27347e-06</iyz>
            <izz>0.011764</izz>
          </inertia>
        </inertial>
        <gravity>1</gravity>
        <velocity_decay>
          <linear>0</linear>
          <angular>0</angular>
        </velocity_decay>
        <self_collide>0</self_collide>
        <kinematic>0</kinematic>
      </link>
      <joint name='caster_joint_br' type='revolute'>
        <child>caster_link_br</child>
        <parent>base_footprint</parent>
        <axis>
          <xyz>0 0 1</xyz>
          <limit>
            <lower>-1e+16</lower>
            <upper>1e+16</upper>
          </limit>
          <dynamics>
            <damping>1</damping>
          </dynamics>
        </axis>
      </joint>
      <link name='wheel_link_br'>
        <pose>-0.228 -0.158 -0.034 0 -0 0</pose>
        <inertial>
          <pose>0 0 0 0 -0 0</pose>
          <mass>0.4</mass>
          <inertia>
            <ixx>0.0124118</ixx>
            <ixy>-0.000711734</ixy>
            <ixz>0.00050273</ixz>
            <iyy>0.0152182</iyy>
            <iyz>-4.27347e-06</iyz>
            <izz>0.011764</izz>
          </inertia>
        </inertial>
        <collision name='wheel_link_br_collision'>
          <pose>0 0 0 1.5708 -0 0</pose>
          <geometry>
            <cylinder>
              <length>0.05</length>
              <radius>0.05</radius>
            </cylinder>
          </geometry>
          <surface>
            <contact>
              <ode>
                <kp>1e+06</kp>
                <kd>100</kd>
              </ode>
            </contact>
            <friction>
              <ode/>
            </friction>
            <bounce/>
          </surface>
          <max_contacts>10</max_contacts>
        </collision>
        <visual name='wheel_link_br_visual'>
          <pose>0 0 0 0 -0 0</pose>
          <geometry>
            <sphere>
              <radius>0.05</radius>
            </sphere>
          </geometry>
          <material>
            <script>
              <name>youbot/Orange</name>
              <uri>__default__</uri>
            </script>
          </material>
        </visual>
        <gravity>1</gravity>
        <velocity_decay>
          <linear>0</linear>
          <angular>0</angular>
        </velocity_decay>
        <self_collide>0</self_collide>
        <kinematic>0</kinematic>
      </link>
      <joint name='wheel_joint_br' type='revolute'>
        <child>wheel_link_br</child>
        <parent>caster_link_br</parent>
        <axis>
          <xyz>0 1 0</xyz>
          <limit>
            <lower>-1e+16</lower>
            <upper>1e+16</upper>
          </limit>
          <dynamics>
            <damping>1</damping>
          </dynamics>
        </axis>
      </joint>
      <link name='caster_link_fl'>
        <pose>0.228 0.158 -0.034 0 -0 0</pose>
        <inertial>
          <pose>0 0 0 0 -0 0</pose>
          <mass>0.1</mass>
          <inertia>
            <ixx>0.0124118</ixx>
            <ixy>-0.000711734</ixy>
            <ixz>0.00050273</ixz>
            <iyy>0.0152182</iyy>
            <iyz>-4.27347e-06</iyz>
            <izz>0.011764</izz>
          </inertia>
        </inertial>
        <gravity>1</gravity>
        <velocity_decay>
          <linear>0</linear>
          <angular>0</angular>
        </velocity_decay>
        <self_collide>0</self_collide>
        <kinematic>0</kinematic>
      </link>
      <joint name='caster_joint_fl' type='revolute'>
        <child>caster_link_fl</child>
        <parent>base_footprint</parent>
        <axis>
          <xyz>0 0 1</xyz>
          <limit>
            <lower>-1e+16</lower>
            <upper>1e+16</upper>
          </limit>
          <dynamics>
            <damping>1</damping>
          </dynamics>
        </axis>
      </joint>
      <link name='wheel_link_fl'>
        <pose>0.228 0.158 -0.034 0 -0 0</pose>
        <inertial>
          <pose>0 0 0 0 -0 0</pose>
          <mass>0.4</mass>
          <inertia>
            <ixx>0.0124118</ixx>
            <ixy>-0.000711734</ixy>
            <ixz>0.00050273</ixz>
            <iyy>0.0152182</iyy>
            <iyz>-4.27347e-06</iyz>
            <izz>0.011764</izz>
          </inertia>
        </inertial>
        <collision name='wheel_link_fl_collision'>
          <pose>0 0 0 1.5708 -0 0</pose>
          <geometry>
            <cylinder>
              <length>0.05</length>
              <radius>0.05</radius>
            </cylinder>
          </geometry>
          <surface>
            <contact>
              <ode>
                <kp>1e+06</kp>
                <kd>100</kd>
              </ode>
            </contact>
            <friction>
              <ode/>
            </friction>
            <bounce/>
          </surface>
          <max_contacts>10</max_contacts>
        </collision>
        <visual name='wheel_link_fl_visual'>
          <pose>0 0 0 0 -0 0</pose>
          <geometry>
            <sphere>
              <radius>0.05</radius>
            </sphere>
          </geometry>
          <material>
            <script>
              <name>youbot/Orange</name>
              <uri>__default__</uri>
            </script>
          </material>
        </visual>
        <gravity>1</gravity>
        <velocity_decay>
          <linear>0</linear>
          <angular>0</angular>
        </velocity_decay>
        <self_collide>0</self_collide>
        <kinematic>0</kinematic>
      </link>
      <joint name='wheel_joint_fl' type='revolute'>
        <child>wheel_link_fl</child>
        <parent>caster_link_fl</parent>
        <axis>
          <xyz>0 1 0</xyz>
          <limit>
            <lower>-1e+16</lower>
            <upper>1e+16</upper>
          </limit>
          <dynamics>
            <damping>1</damping>
          </dynamics>
        </axis>
      </joint>
      <link name='caster_link_fr'>
        <pose>0.228 -0.158 -0.034 0 -0 0</pose>
        <inertial>
          <pose>0 0 0 0 -0 0</pose>
          <mass>0.1</mass>
          <inertia>
            <ixx>0.0124118</ixx>
            <ixy>-0.000711734</ixy>
            <ixz>0.00050273</ixz>
            <iyy>0.0152182</iyy>
            <iyz>-4.27347e-06</iyz>
            <izz>0.011764</izz>
          </inertia>
        </inertial>
        <gravity>1</gravity>
        <velocity_decay>
          <linear>0</linear>
          <angular>0</angular>
        </velocity_decay>
        <self_collide>0</self_collide>
        <kinematic>0</kinematic>
      </link>
      <joint name='caster_joint_fr' type='revolute'>
        <child>caster_link_fr</child>
        <parent>base_footprint</parent>
        <axis>
          <xyz>0 0 1</xyz>
          <limit>
            <lower>-1e+16</lower>
            <upper>1e+16</upper>
          </limit>
          <dynamics>
            <damping>1</damping>
          </dynamics>
        </axis>
      </joint>
      <link name='wheel_link_fr'>
        <pose>0.228 -0.158 -0.034 0 -0 0</pose>
        <inertial>
          <pose>0 0 0 0 -0 0</pose>
          <mass>0.4</mass>
          <inertia>
            <ixx>0.0124118</ixx>
            <ixy>-0.000711734</ixy>
            <ixz>0.00050273</ixz>
            <iyy>0.0152182</iyy>
            <iyz>-4.27347e-06</iyz>
            <izz>0.011764</izz>
          </inertia>
        </inertial>
        <collision name='wheel_link_fr_collision'>
          <pose>0 0 0 1.5708 -0 0</pose>
          <geometry>
            <cylinder>
              <length>0.05</length>
              <radius>0.05</radius>
            </cylinder>
          </geometry>
          <surface>
            <contact>
              <ode>
                <kp>1e+06</kp>
                <kd>100</kd>
              </ode>
            </contact>
            <friction>
              <ode/>
            </friction>
            <bounce/>
          </surface>
          <max_contacts>10</max_contacts>
        </collision>
        <visual name='wheel_link_fr_visual'>
          <pose>0 0 0 0 -0 0</pose>
          <geometry>
            <sphere>
              <radius>0.05</radius>
            </sphere>
          </geometry>
          <material>
            <script>
              <name>youbot/Orange</name>
              <uri>__default__</uri>
            </script>
          </material>
        </visual>
        <gravity>1</gravity>
        <velocity_decay>
          <linear>0</linear>
          <angular>0</angular>
        </velocity_decay>
        <self_collide>0</self_collide>
        <kinematic>0</kinematic>
      </link>
      <joint name='wheel_joint_fr' type='revolute'>
        <child>wheel_link_fr</child>
        <parent>caster_link_fr</parent>
        <axis>
          <xyz>0 1 0</xyz>
          <limit>
            <lower>-1e+16</lower>
            <upper>1e+16</upper>
          </limit>
          <dynamics>
            <damping>1</damping>
          </dynamics>
        </axis>
      </joint>
      <plugin name='gazebo_ros_controller' filename='libgazebo_ros_control.so'>
        <robotNamespace>/</robotNamespace>
      </plugin>
      <static>0</static>
      <plugin name='base_controller' filename='libgazebo_ros_planar_move.so'>
        <commandTopic>cmd_vel</commandTopic>
        <odometryTopic>odom</odometryTopic>
        <odometryFrame>odom</odometryFrame>
        <odometryRate>100.0</odometryRate>
        <robotBaseFrame>base_footprint</robotBaseFrame>
        <robotNamespace>/</robotNamespace>
      </plugin>
      <pose>0 0 0 0 -0 0</pose>
    </model>
    <state world_name='default'>
      <sim_time>135 297000000</sim_time>
      <real_time>137 450705398</real_time>
      <wall_time>1390248712 848442903</wall_time>
      <model name='ground_plane'>
        <pose>0 0 0 0 -0 0</pose>
        <link name='link'>
          <pose>0 0 0 0 -0 0</pose>
          <velocity>0 0 0 0 -0 0</velocity>
          <acceleration>0 0 0 0 -0 0</acceleration>
          <wrench>0 0 0 0 -0 0</wrench>
        </link>
      </model>
      <model name='youbot'>
        <pose>-0.000678 -4e-06 0.083959 -2e-06 2.3e-05 2.5e-05</pose>
        <link name='arm_link_1'>
          <pose>0.166325 1e-06 0.225956 5e-06 -2.3e-05 2.96619</pose>
          <velocity>0.000255 -2.3e-05 -0.005962 9.3e-05 0.001016 -0.002198</velocity>
          <acceleration>0 0 0 0 -0 0</acceleration>
          <wrench>0 0 0 0 -0 0</wrench>
        </link>
        <link name='arm_link_2'>
          <pose>0.133831 0.00576 0.244956 8e-06 -1.10367 2.96619</pose>
          <velocity>0.000307 3.5e-05 -0.00593 -0.005675 -0.031271 -0.002112</velocity>
          <acceleration>0 0 0 0 -0 0</acceleration>
          <wrench>0 0 0 0 -0 0</wrench>
        </link>
        <link name='arm_link_3'>
          <pose>0.270103 -0.01839 0.314755 4e-06 1.2669 2.9662</pose>
          <velocity>-0.001927 0.000132 -0.001525 0.002737 0.016425 -0.002142</velocity>
          <acceleration>0 0 0 0 -0 0</acceleration>
          <wrench>0 0 0 0 -0 0</wrench>
        </link>
        <link name='arm_link_4'>
          <pose>0.143266 0.004088 0.355152 -4e-06 -0.357584 2.96619</pose>
          <velocity>-0.001206 0.000288 0.000623 0.000441 0.004031 -0.002049</velocity>
          <acceleration>0 0 0 0 -0 0</acceleration>
          <wrench>0 0 0 0 -0 0</wrench>
        </link>
        <link name='arm_link_5'>
          <pose>0.189914 -0.004179 0.47623 -0.093684 0.345604 -0.445963</pose>
          <velocity>-0.000726 0.000122 0.000421 0.001183 0.003932 -0.000201</velocity>
          <acceleration>0 0 0 0 -0 0</acceleration>
          <wrench>0 0 0 0 -0 0</wrench>
        </link>
        <link name='base_footprint'>
          <pose>-0.000678 -4e-06 0.083959 -2e-06 2.3e-05 2.5e-05</pose>
          <velocity>0.000109 -1.6e-05 -0.005797 1.8e-05 0.001001 -2e-05</velocity>
          <acceleration>0 0 0 0 -0 0</acceleration>
          <wrench>0 0 0 0 -0 0</wrench>
        </link>
        <link name='caster_link_bl'>
          <pose>-0.228683 0.15799 0.049966 -2e-06 2.3e-05 0.002581</pose>
          <velocity>5e-05 -3e-06 -0.00571 2.5e-05 0.001001 -3.2e-05</velocity>
          <acceleration>0 0 0 0 -0 0</acceleration>
          <wrench>0 0 0 0 -0 0</wrench>
        </link>
        <link name='caster_link_br'>
          <pose>-0.228675 -0.158009 0.049967 -2e-06 2.3e-05 0.00101</pose>
          <velocity>4.6e-05 -3e-06 -0.005693 2.5e-05 0.001002 -3.2e-05</velocity>
          <acceleration>0 0 0 0 -0 0</acceleration>
          <wrench>0 0 0 0 -0 0</wrench>
        </link>
        <link name='caster_link_fl'>
          <pose>0.227317 0.158002 0.049957 -2e-06 2.3e-05 0.001707</pose>
          <velocity>5e-05 -6e-06 -0.006389 3.2e-05 0.001003 -3.4e-05</velocity>
          <acceleration>0 0 0 0 -0 0</acceleration>
          <wrench>0 0 0 0 -0 0</wrench>
        </link>
        <link name='caster_link_fr'>
          <pose>0.227325 -0.157998 0.049954 -2e-06 2.3e-05 0.001886</pose>
          <velocity>8e-05 -2.4e-05 -0.00593 1.5e-05 0.001 -3e-05</velocity>
          <acceleration>0 0 0 0 -0 0</acceleration>
          <wrench>0 0 0 0 -0 0</wrench>
        </link>
        <link name='gripper_finger_link_l'>
          <pose>0.212864 -0.00019 0.517152 0.093684 -0.345604 2.69563</pose>
          <velocity>-0.000487 0.000245 0.000318 0.001185 0.003935 -0.000202</velocity>
          <acceleration>0 0 0 0 -0 0</acceleration>
          <wrench>0 0 0 0 -0 0</wrench>
        </link>
        <link name='gripper_finger_link_r'>
          <pose>0.201568 -0.025889 0.519632 -0.093684 0.345604 -0.445963</pose>
          <velocity>-0.000482 0.000244 0.000332 0.001191 0.003941 -0.000204</velocity>
          <acceleration>0 0 0 0 -0 0</acceleration>
          <wrench>0 0 0 0 -0 0</wrench>
        </link>
        <link name='wheel_link_bl'>
          <pose>-0.228683 0.15799 0.049966 -3e-06 -0.013567 0.002582</pose>
          <velocity>4.4e-05 -2e-06 -0.005694 3.3e-05 0.000888 -2.8e-05</velocity>
          <acceleration>0 0 0 0 -0 0</acceleration>
          <wrench>0 0 0 0 -0 0</wrench>
        </link>
        <link name='wheel_link_br'>
          <pose>-0.228675 -0.158009 0.049967 -1e-06 -0.013565 0.00101</pose>
          <velocity>4.1e-05 -2e-06 -0.005679 3.3e-05 0.000818 -2.8e-05</velocity>
          <acceleration>0 0 0 0 -0 0</acceleration>
          <wrench>0 0 0 0 -0 0</wrench>
        </link>
        <link name='wheel_link_fl'>
          <pose>0.227317 0.158002 0.049957 -2e-06 -0.012975 0.001707</pose>
          <velocity>4.5e-05 -2e-06 -0.006349 4.8e-05 0.000896 -3.1e-05</velocity>
          <acceleration>0 0 0 0 -0 0</acceleration>
          <wrench>0 0 0 0 -0 0</wrench>
        </link>
        <link name='wheel_link_fr'>
          <pose>0.227325 -0.157998 0.049957 -2e-06 -0.013654 0.001887</pose>
          <velocity>4.1e-05 -2e-06 -0.006306 4.8e-05 0.000826 -2.8e-05</velocity>
          <acceleration>0 0 0 0 -0 0</acceleration>
          <wrench>0 0 0 0 -0 0</wrench>
        </link>
      </model>
    </state>
    <gui fullscreen='0'>
      <camera name='user_camera'>
        <pose>3.16896 -3.80862 1.27231 0 0.275643 2.35619</pose>
        <view_controller>orbit</view_controller>
      </camera>
    </gui>
  </world>
</sdf>
